Workbook

Sheet Referrals
B2: Referral ID | C2: Week Number | D2: Child Name | E2: Placement Officer Assigned | F2: Vacant carers | G2: Calls Made | H2: Carer Found? | I2: Outcome
B3: 1 | C3: =CEILING(Referral[[#This Row],[Referral ID]]/50,1) -> 1 | D3: Oliver Bennett | E3: Chen Wei | F3: 8 | G3: 7 | H3: {=OR(_xlfn._xlws.FILTER('Call Log'!$D$4:$D$381,Table5[Referral ID]=Referral[[#This Row],[Referral ID]]))} -> FALSE | I3: =IF(Referral[[#This Row],[Carer Found?]], "Fostering", "Residential") -> Residential
B4: 2 | C4: =CEILING(Referral[[#This Row],[Referral ID]]/50,1) -> 1 | D4: Kwame Mensah | E4: Chen Wei | F4: 6 | G4: 5 | H4: {=OR(_xlfn._xlws.FILTER('Call Log'!$D$4:$D$381,Table5[Referral ID]=Referral[[#This Row],[Referral ID]]))} -> TRUE | I4: =IF(Referral[[#This Row],[Carer Found?]], "Fostering", "Residential") -> Fostering
B5: 3 | C5: =CEILING(Referral[[#This Row],[Referral ID]]/50,1) -> 1 | D5: Amelia Clarke | E5: Ananya Joshi | F5: 10 | G5: 2 | H5: {=OR(_xlfn._xlws.FILTER('Call Log'!$D$4:$D$381,Table5[Referral ID]=Referral[[#This Row],[Referral ID]]))} -> TRUE | I5: =IF(Referral[[#This Row],[Carer Found?]], "Fostering", "Residential") -> Fostering
B6: 4 | C6: =CEILING(Referral[[#This Row],[Referral ID]]/50,1) -> 1 | D6: Wei Li | E6: Simran Kaur | F6: 3 | G6: 3 | H6: {=OR(_xlfn._xlws.FILTER('Call Log'!$D$4:$D$381,Table5[Referral ID]=Referral[[#This Row],[Referral ID]]))} -> FALSE | I6: =IF(Referral[[#This Row],[Carer Found?]], "Fostering", "Residential") -> Residential
B7: 5 | C7: =CEILING(Referral[[#This Row],[Referral ID]]/50,1) -> 1 | D7: Isla MacLeod | E7: Mateusz Kowalski | F7: 14 | G7: 6 | H7: {=OR(_xlfn._xlws.FILTER('Call Log'!$D$4:$D$381,Table5[Referral ID]=Referral[[#This Row],[Referral ID]]))} -> TRUE | I7: =IF(Referral[[#This Row],[Carer Found?]], "Fostering", "Residential") -> Fostering | K7: Residential | L7: Fostering
B8: 6 | C8: =CEILING(Referral[[#This Row],[Referral ID]]/50,1) -> 1 | D8: Louis Barker | E8: Chen Wei | F8: 4 | G8: 4 | H8: {=OR(_xlfn._xlws.FILTER('Call Log'!$D$4:$D$381,Table5[Referral ID]=Referral[[#This Row],[Referral ID]]))} -> FALSE | I8: =IF(Referral[[#This Row],[Carer Found?]], "Fostering", "Residential") -> Residential | K8: =COUNTIF(Referral[Outcome],"Residential") -> 40 | L8: =COUNTIF(Referral[Outcome],"Fostering") -> 60
B9: 7 | C9: =CEILING(Referral[[#This Row],[Referral ID]]/50,1) -> 1 | D9: Aisha Khan | E9: Elinor Price | F9: 2 | G9: 2 | H9: {=OR(_xlfn._xlws.FILTER('Call Log'!$D$4:$D$381,Table5[Referral ID]=Referral[[#This Row],[Referral ID]]))} -> FALSE | I9: =IF(Referral[[#This Row],[Carer Found?]], "Fostering", "Residential") -> Residential
B10: 8 | C10: =CEILING(Referral[[#This Row],[Referral ID]]/50,1) -> 1 | D10: Harper Simmons | E10: Fatima Noor | F10: 8 | G10: 6 | H10: {=OR(_xlfn._xlws.FILTER('Call Log'!$D$4:$D$381,Table5[Referral ID]=Referral[[#This Row],[Referral ID]]))} -> FALSE | I10: =IF(Referral[[#This Row],[Carer Found?]], "Fostering", "Residential") -> Residential
B11: 9 | C11: =CEILING(Referral[[#This Row],[Referral ID]]/50,1) -> 1 | D11: Rohan Choudhury | E11: Elinor Price | F11: 3 | G11: 3 | H11: {=OR(_xlfn._xlws.FILTER('Call Log'!$D$4:$D$381,Table5[Referral ID]=Referral[[#This Row],[Referral ID]]))} -> TRUE | I11: =IF(Referral[[#This Row],[Carer Found?]], "Fostering", "Residential") -> Fostering
B12: 10 | C12: =CEILING(Referral[[#This Row],[Referral ID]]/50,1) -> 1 | D12: Oscar Palmer | E12: Declan McBride | F12: 11 | G12: 6 | H12: {=OR(_xlfn._xlws.FILTER('Call Log'!$D$4:$D$381,Table5[Referral ID]=Referral[[#This Row],[Referral ID]]))} -> TRUE | I12: =IF(Referral[[#This Row],[Carer Found?]], "Fostering", "Residential") -> Fostering
B13: 11 | C13: =CEILING(Referral[[#This Row],[Referral ID]]/50,1) -> 1 | D13: Nancy Curtis | E13: Mateusz Kowalski | F13: 6 | G13: 5 | H13: {=OR(_xlfn._xlws.FILTER('Call Log'!$D$4:$D$381,Table5[Referral ID]=Referral[[#This Row],[Referral ID]]))} -> TRUE | I13: =IF(Referral[[#This Row],[Carer Found?]], "Fostering", "Residential") -> Fostering
B14: 12 | C14: =CEILING(Referral[[#This Row],[Referral ID]]/50,1) -> 1 | D14: Dominic Sharp | E14: Mateusz Kowalski | F14: 6 | G14: 1 | H14: {=OR(_xlfn._xlws.FILTER('Call Log'!$D$4:$D$381,Table5[Referral ID]=Referral[[#This Row],[Referral ID]]))} -> FALSE | I14: =IF(Referral[[#This Row],[Carer Found?]], "Fostering", "Residential") -> Residential
B15: 13 | C15: =CEILING(Referral[[#This Row],[Referral ID]]/50,1) -> 1 | D15: Rosie Webb | E15: Kwesi Boateng | F15: 3 | G15: 3 | H15: {=OR(_xlfn._xlws.FILTER('Call Log'!$D$4:$D$381,Table5[Referral ID]=Referral[[#This Row],[Referral ID]]))} -> FALSE | I15: =IF(Referral[[#This Row],[Carer Found?]], "Fostering", "Residential") -> Residential
B16: 14 | C16: =CEILING(Referral[[#This Row],[Referral ID]]/50,1) -> 1 | D16: Meera Desai | E16: Luca Romano | F16: 6 | G16: 6 | H16: {=OR(_xlfn._xlws.FILTER('Call Log'!$D$4:$D$381,Table5[Referral ID]=Referral[[#This Row],[Referral ID]]))} -> TRUE | I16: =IF(Referral[[#This Row],[Carer Found?]], "Fostering", "Residential") -> Fostering
B17: 15 | C17: =CEILING(Referral[[#This Row],[Referral ID]]/50,1) -> 1 | D17: Hugo Fraser | E17: Simran Kaur | F17: 5 | G17: 5 | H17: {=OR(_xlfn._xlws.FILTER('Call Log'!$D$4:$D$381,Table5[Referral ID]=Referral[[#This Row],[Referral ID]]))} -> TRUE | I17: =IF(Referral[[#This Row],[Carer Found?]], "Fostering", "Residential") -> Fostering
B18: 16 | C18: =CEILING(Referral[[#This Row],[Referral ID]]/50,1) -> 1 | D18: Chinedu Okafor | E18: Declan McBride | F18: 3 | G18: 3 | H18: {=OR(_xlfn._xlws.FILTER('Call Log'!$D$4:$D$381,Table5[Referral ID]=Referral[[#This Row],[Referral ID]]))} -> TRUE | I18: =IF(Referral[[#This Row],[Carer Found?]], "Fostering", "Residential") -> Fostering
B19: 17 | C19: =CEILING(Referral[[#This Row],[Referral ID]]/50,1) -> 1 | D19: Elliott Ford | E19: Elinor Price | F19: 4 | G19: 4 | H19: {=OR(_xlfn._xlws.FILTER('Call Log'!$D$4:$D$381,Table5[Referral ID]=Referral[[#This Row],[Referral ID]]))} -> TRUE | I19: =IF(Referral[[#This Row],[Carer Found?]], "Fostering", "Residential") -> Fostering
B20: 18 | C20: =CEILING(Referral[[#This Row],[Referral ID]]/50,1) -> 1 | D20: Bonnie Clarke | E20: Kwesi Boateng | F20: 0 | G20: 0 | H20: {=OR(_xlfn._xlws.FILTER('Call Log'!$D$4:$D$381,Table5[Referral ID]=Referral[[#This Row],[Referral ID]]))} -> FALSE | I20: =IF(Referral[[#This Row],[Carer Found?]], "Fostering", "Residential") -> Residential
... B102: 100 | C102: =CEILING(Referral[[#This Row],[Referral ID]]/50,1) -> 2 | D102: Rochelle Lewis | E102: Simran Kaur | F102: 5 | G102: 5 | H102: {=OR(_xlfn._xlws.FILTER('Call Log'!$D$4:$D$381,Table5[Referral ID]=Referral[[#This Row],[Referral ID]]))} -> TRUE | I102: =IF(Referral[[#This Row],[Carer Found?]], "Fostering", "Residential") -> Fostering
F103: =SUM(Referral[Vacant carers]) -> 518 | G103: =SUM(Referral[Calls Made]) -> 366

Sheet Call Log
B2: Referral ID | C2: Index | D2: Carer Accepted? | E2: Reason for Decline
B3: 1 | C3: 0 | D3: FALSE
B4: 1 | C4: 1 | D4: FALSE
B5: 1 | C5: 2 | D5: FALSE
B6: 1 | C6: 3 | D6: FALSE
B7: 1 | C7: 4 | D7: FALSE
B8: 1 | C8: 5 | D8: FALSE
B9: 1 | C9: 6 | D9: FALSE | E9: Carer cannot provide transport for YP
B10: 2 | C10: 0 | D10: FALSE
B11: 2 | C11: 1 | D11: FALSE | E11: Carer cannot provide transport for YP
B12: 2 | C12: 2 | D12: FALSE
B13: 2 | C13: 3 | D13: FALSE
B14: 2 | C14: 4 | D14: TRUE
B15: 3 | C15: 0 | D15: FALSE | E15: Carer not trained in needs of YP
B16: 3 | C16: 1 | D16: TRUE
B17: 4 | C17: 0 | D17: FALSE
B18: 4 | C18: 1 | D18: FALSE | E18: Other
B19: 4 | C19: 2 | D19: FALSE
B20: 5 | C20: 0 | D20: FALSE
B21: 5 | C21: 1 | D21: FALSE
B22: 5 | C22: 2 | D22: FALSE
B23: 5 | C23: 3 | D23: FALSE
B24: 5 | C24: 4 | D24: FALSE | E24: Carer cannot provide transport for YP
B25: 5 | C25: 5 | D25: TRUE
B26: 6 | C26: 0 | D26: FALSE
B27: 6 | C27: 1 | D27: FALSE
B28: 6 | C28: 2 | D28: FALSE
B29: 6 | C29: 3 | D29: FALSE | E29: Carer was incorrectly recorded as vacant
B30: 7 | C30: 0 | D30: FALSE
B31: 7 | C31: 1 | D31: FALSE
B32: 8 | C32: 0 | D32: FALSE | E32: Carer was incorrectly recorded as vacant
B33: 8 | C33: 1 | D33: FALSE | E33: Carer cannot provide transport for YP
B34: 8 | C34: 2 | D34: FALSE
B35: 8 | C35: 3 | D35: FALSE
B36: 8 | C36: 4 | D36: FALSE
B37: 8 | C37: 5 | D37: FALSE | E37: Carer cannot provide transport for YP
B38: 9 | C38: 0 | D38: FALSE | E38: Carer cannot provide transport for YP
B39: 9 | C39: 1 | D39: FALSE
B40: 9 | C40: 2 | D40: TRUE
B41: 10 | C41: 0 | D41: FALSE
...

Sheet Call Log Full
B2: Referral ID | C2: Index | D2: Carer Found? | E2: Reason for Decline
B3: 1 | C3: 0 | D3: FALSE | E3: Carer was incorrectly recorded as vacant
B4: 1 | C4: 1 | D4: FALSE | E4: Not a good match for carer
B5: 1 | C5: 2 | D5: FALSE | E5: Carer cannot provide transport for YP
B6: 1 | C6: 3 | D6: FALSE | E6: Carer was incorrectly recorded as vacant
B7: 1 | C7: 4 | D7: FALSE | E7: Carer was incorrectly recorded as vacant
B8: 1 | C8: 5 | D8: FALSE | E8: Not a good match for carer
B9: 1 | C9: 6 | D9: FALSE | E9: Carer cannot provide transport for YP
B10: 2 | C10: 0 | D10: FALSE | E10: Carer cannot provide transport for YP
B11: 2 | C11: 1 | D11: FALSE | E11: Carer cannot provide transport for YP
B12: 2 | C12: 2 | D12: FALSE | E12: Carer was incorrectly recorded as vacant
B13: 2 | C13: 3 | D13: FALSE | E13: Carer not trained in needs of YP
B14: 2 | C14: 4 | D14: TRUE
B15: 3 | C15: 0 | D15: FALSE | E15: Carer not trained in needs of YP
B16: 3 | C16: 1 | D16: TRUE
B17: 4 | C17: 0 | D17: FALSE | E17: Carer cannot provide transport for YP
B18: 4 | C18: 1 | D18: FALSE | E18: Other
B19: 4 | C19: 2 | D19: FALSE | E19: Carer not trained in needs of YP
B20: 5 | C20: 0 | D20: FALSE | E20: Carer was incorrectly recorded as vacant
B21: 5 | C21: 1 | D21: FALSE | E21: Carer cannot provide transport for YP
B22: 5 | C22: 2 | D22: FALSE | E22: Carer was incorrectly recorded as vacant
B23: 5 | C23: 3 | D23: FALSE | E23: Carer was incorrectly recorded as vacant
B24: 5 | C24: 4 | D24: FALSE | E24: Carer cannot provide transport for YP
B25: 5 | C25: 5 | D25: TRUE
B26: 6 | C26: 0 | D26: FALSE | E26: Carer not trained in needs of YP
B27: 6 | C27: 1 | D27: FALSE | E27: Carer cannot provide transport for YP
B28: 6 | C28: 2 | D28: FALSE | E28: Carer was incorrectly recorded as vacant
B29: 6 | C29: 3 | D29: FALSE | E29: Carer was incorrectly recorded as vacant
B30: 7 | C30: 0 | D30: FALSE | E30: Other
B31: 7 | C31: 1 | D31: FALSE | E31: Carer not trained in needs of YP
B32: 8 | C32: 0 | D32: FALSE | E32: Carer was incorrectly recorded as vacant
B33: 8 | C33: 1 | D33: FALSE | E33: Carer cannot provide transport for YP
B34: 8 | C34: 2 | D34: FALSE | E34: Carer was incorrectly recorded as vacant
B35: 8 | C35: 3 | D35: FALSE | E35: Carer cannot provide transport for YP
B36: 8 | C36: 4 | D36: FALSE | E36: Carer cannot provide transport for YP
B37: 8 | C37: 5 | D37: FALSE | E37: Carer cannot provide transport for YP
... B39: 9 | C39: 1 | D39: FALSE | E39: Carer was incorrectly recorded as vacant
B40: 9 | C40: 2 | D40: TRUE
B41: 10 | C41: 0 | D41: FALSE | E41: Carer was incorrectly recorded as vacant
B42: 10 | C42: 1 | D42: FALSE | E42: Other
...

Sheet POs
B2: Name
B3: Ananya Joshi
B4: Declan McBride
B5: Fatima Noor
B6: Luca Romano
B7: Chen Wei
B8: Simran Kaur
B9: Kwesi Boateng
B10: Elinor Price
B11: Mateusz Kowalski
B12: Soraya Haddad
